<?xml version="1.0"?>
<sdf version="1.7">
	<model name="HoppingRobot2d">
		<link name="base_link">
			<pose>0 0 0 0 0 0</pose>
			<inertial>
				<pose>0 0 0 0 0 0</pose>
				<mass>1.4</mass>
				<inertia>
					<ixx>0.0023</ixx>
					<ixy>0</ixy>
					<ixz>0</ixz>
					<iyy>0.0023</iyy>
					<iyz>0</iyz>
					<izz>0.0023</izz>
				</inertia>
			</inertial>
			<!-- <collision name="base_link_collision">
				<geometry>
					<box>
						<size>0.1 0.1 0.1</size>
					</box>
				</geometry>
			</collision> -->
			<visual name="base_link_visual">
				<geometry>
					<box>
						<size>0.1 0.1 0.1</size>
					</box>
				</geometry>
			</visual>
		</link>

		<link name="upper_link">
			<pose relative_to="base_link">0 0 0 0 0 0</pose>
			<inertial>
				<pose>0 0 -0.1 0 0 0</pose>
				<mass>0.5</mass>
				<inertia>
					<ixx>0.0017</ixx>
					<ixy>0</ixy>
					<ixz>0</ixz>
					<iyy>0.0017</iyy>
					<iyz>0</iyz>
					<izz>0.00005625</izz>
				</inertia>
			</inertial>
			<!-- <collision name="upper_link_collision">
				<pose>0 0 -0.1 0 0 0</pose>
				<geometry>
					<cylinder>
						<length>0.2</length>
						<radius>0.015</radius>
					</cylinder>
				</geometry>
			</collision> -->
			<visual name="upper_link_visual">
				<pose>0 0 -0.1 0 0 0</pose>
				<geometry>
					<cylinder>
						<length>0.2</length>
						<radius>0.015</radius>
					</cylinder>
				</geometry>
			</visual>
		</link>
		<joint name="shoulder" type="fixed">
			<child>upper_link</child>
			<parent>base_link</parent>
			<!-- <axis>
				<xyz expressed_in="__model__">0 1 0</xyz>
				<limit>
				</limit>
				<dynamics>
					<damping>0.1</damping>
					<friction>0</friction>
					<spring_reference>0</spring_reference>
					<spring_stiffness>0</spring_stiffness>
				</dynamics>
			</axis> -->
		</joint>

		<link name="lower_link">
			<pose relative_to="upper_link">0 0 -0.2 0 0 0</pose>
			<inertial>
				<pose>0 0 -0.05 0 0 0</pose>
				<mass>0.3</mass>
				<inertia>
					<ixx>0.00075</ixx>
					<ixy>0</ixy>
					<ixz>0</ixz>
					<iyy>0.00075</iyy>
					<iyz>0</iyz>
					<izz>0.000005</izz>
				</inertia>
			</inertial>
			<!-- <collision name="lower_link_collision">
				<pose>0 0 -0.05 0 0 0</pose>
				<geometry>
					<cylinder>
						<length>0.1</length>
						<radius>0.01</radius>
					</cylinder>
				</geometry>
			</collision> -->
			<visual name="lower_link_visual">
				<pose>0 0 -0.05 0 0 0</pose>
				<geometry>
					<cylinder>
						<length>0.1</length>
						<radius>0.01</radius>
					</cylinder>
				</geometry>
			</visual>
		</link>
		<joint name="elbow" type="revolute">
			<child>lower_link</child>
			<parent>upper_link</parent>
			<axis>
				<xyz expressed_in="__model__">0 1 0</xyz>
				<limit>
					<!-- 2.36 = 3/4*pi = 135 degrees-->
					<lower>-2.36</lower>
					<upper>2.36</upper>
				</limit>
				<dynamics>
					<damping>0.1</damping>
					<friction>0</friction>
					<spring_reference>0</spring_reference>
					<spring_stiffness>0</spring_stiffness>
				</dynamics>
			</axis>
		</joint>

		<link name="foot_link">
			<pose relative_to="lower_link">0 0.0 -0.1 0 0 0</pose>
			<inertial>
				<pose>0 0 -0.05 0 0 0</pose>
				<mass>0.3</mass>
				<inertia>
					<ixx>0.00075</ixx>
					<ixy>0</ixy>
					<ixz>0</ixz>
					<iyy>0.00075</iyy>
					<iyz>0</iyz>
					<izz>0.000005</izz>
				</inertia>
			</inertial>
			<collision name="foot_sphere_collision">
				<pose>0 0 -0.1 0 0 0</pose>
				<geometry>
					<sphere>
						<radius>0.01</radius>
					</sphere>
				</geometry>
			</collision>
			<visual name="foot_link_visual">
				<pose>0 0 -0.05 0 0 0</pose>
				<geometry>
					<cylinder>
						<length>0.1</length>
						<radius>0.005</radius>
					</cylinder>
				</geometry>
			</visual>
			<visual name="foot_sphere_visual">
				<pose>0 0 -0.1 0 0 0</pose>
				<geometry>
					<sphere>
						<radius>0.01</radius>
					</sphere>
				</geometry>
			</visual>
		</link>
		<joint name="spring" type="prismatic">
			<child>foot_link</child>
			<parent>lower_link</parent>
			<axis>
				<xyz expressed_in="__model__">0 0 1</xyz>
				<limit>
					<lower>-0.15</lower>
					<upper>0.15</upper>
				</limit>
				<dynamics>
					<damping>0.2</damping>
					<friction>0</friction>
					<spring_reference>0</spring_reference>
					<spring_stiffness>1000</spring_stiffness>
				</dynamics>
			</axis>
		</joint>
		<frame name="foot" attached_to="foot_link">
			<pose relative_to="foot_link">0 0 -0.1 0 0 0</pose>
		</frame>
	</model>
</sdf>